Workbook

Sheet Data
B2: Date | C2: Month (old) | D2: Symbol (old) | E2: Open (US$) | F2: High Open (US$) | G2: Low Open (US$) | H2: Close Open (US$) | I2: Volume | J2: Month (old2) | K2: Symbol | L2: Month
B3: 44561 | C3: December | D3: SP500 | E3: 477521 | F3: 478683 | G3: 476575 | H3: 476618 | I3: 244619000000 | J3: =TRIM(data__2[[#This Row],[Month (old)]]) -> December | K3: =TRIM(data__2[[#This Row],[Symbol (old)]]) -> SP500 | L3: =LEFT(data__2[[#This Row],[Month (old2)]], 3) -> Dec
B4: 44561 | C4: Dec | D4: BTCUSD | E4: 4720799 | F4: 4857835 | G4: 4564111 | H4: 4680683 | I4: 159171 | J4: =TRIM(data__2[[#This Row],[Month (old)]]) -> Dec | K4: =TRIM(data__2[[#This Row],[Symbol (old)]]) -> BTCUSD | L4: =LEFT(data__2[[#This Row],[Month (old2)]], 3) -> Dec
B5: 44560 | C5: December | D5: SP500 | E5: 479423 | F5: 480893 | G5: 477533 | H5: 477873 | I5: 239099000000 | J5: =TRIM(data__2[[#This Row],[Month (old)]]) -> December | K5: =TRIM(data__2[[#This Row],[Symbol (old)]]) -> SP500 | L5: =LEFT(data__2[[#This Row],[Month (old2)]], 3) -> Dec
B6: 44560 | C6: Dec | D6: BTCUSD | E6: 4650244 | F6: 4794930 | G6: 4649619 | H6: 4720799 | I6: 99841 | J6: =TRIM(data__2[[#This Row],[Month (old)]]) -> Dec | K6: =TRIM(data__2[[#This Row],[Symbol (old)]]) -> BTCUSD | L6: =LEFT(data__2[[#This Row],[Month (old2)]], 3) -> Dec
B7: 44559 | C7: December | D7: SP500 | E7: 478864 | F7: 480406 | G7: 477808 | H7: 479306 | I7: 236937000000 | J7: =TRIM(data__2[[#This Row],[Month (old)]]) -> December | K7: =TRIM(data__2[[#This Row],[Symbol (old)]]) -> SP500 | L7: =LEFT(data__2[[#This Row],[Month (old2)]], 3) -> Dec
B8: 44559 | C8: Dec | D8: BTCUSD | E8: 4801793 | F8: 4807597 | G8: 4594530 | H8: 4650244 | I8: 111963 | J8: =TRIM(data__2[[#This Row],[Month (old)]]) -> Dec | K8: =TRIM(data__2[[#This Row],[Symbol (old)]]) -> BTCUSD | L8: =LEFT(data__2[[#This Row],[Month (old2)]], 3) -> Dec
B9: 44558 | C9: December | D9: SP500 | E9: 479549 | F9: 480702 | G9: 478004 | H9: 478635 | I9: 221705000000 | J9: =TRIM(data__2[[#This Row],[Month (old)]]) -> December | K9: =TRIM(data__2[[#This Row],[Symbol (old)]]) -> SP500 | L9: =LEFT(data__2[[#This Row],[Month (old2)]], 3) -> Dec
B10: 44558 | C10: Dec | D10: BTCUSD | E10: 4982179 | F10: 4983468 | G10: 4732297 | H10: 4801793 | I10: 127501 | J10: =TRIM(data__2[[#This Row],[Month (old)]]) -> Dec | K10: =TRIM(data__2[[#This Row],[Symbol (old)]]) -> BTCUSD | L10: =LEFT(data__2[[#This Row],[Month (old2)]], 3) -> Dec
B11: 44557 | C11: December | D11: SP500 | E11: 473399 | F11: 479149 | G11: 473399 | H11: 479119 | I11: 226412000000 | J11: =TRIM(data__2[[#This Row],[Month (old)]]) -> December | K11: =TRIM(data__2[[#This Row],[Symbol (old)]]) -> SP500 | L11: =LEFT(data__2[[#This Row],[Month (old2)]], 3) -> Dec
B12: 44557 | C12: Dec | D12: BTCUSD | E12: 5103612 | F12: 5210493 | G12: 4950947 | H12: 4982179 | I12: 89604 | J12: =TRIM(data__2[[#This Row],[Month (old)]]) -> Dec | K12: =TRIM(data__2[[#This Row],[Symbol (old)]]) -> BTCUSD | L12: =LEFT(data__2[[#This Row],[Month (old2)]], 3) -> Dec
B13: 44556 | C13: Dec | D13: BTCUSD | E13: 4970521 | F13: 5129426 | G13: 4946066 | H13: 5103612 | I13: 48924 | J13: =TRIM(data__2[[#This Row],[Month (old)]]) -> Dec | K13: =TRIM(data__2[[#This Row],[Symbol (old)]]) -> BTCUSD | L13: =LEFT(data__2[[#This Row],[Month (old2)]], 3) -> Dec
B14: 44555 | C14: Dec | D14: BTCUSD | E14: 5087231 | F14: 5115695 | G14: 4965665 | H14: 4970521 | I14: 40067 | J14: =TRIM(data__2[[#This Row],[Month (old)]]) -> Dec | K14: =TRIM(data__2[[#This Row],[Symbol (old)]]) -> BTCUSD | L14: =LEFT(data__2[[#This Row],[Month (old2)]], 3) -> Dec
... B614: 44200 | C614: Jan | D614: BTCUSD | E614: 3361730 | F614: 3366900 | G614: 2763234 | H614: 3120346 | I614: 460392 | J614: =TRIM(data__2[[#This Row],[Month (old)]]) -> Jan | K614: =TRIM(data__2[[#This Row],[Symbol (old)]]) -> BTCUSD | L614: =LEFT(data__2[[#This Row],[Month (old2)]], 3) -> Jan

Sheet Notes
B2: Date | C2: Open Open (US$) | D2: High Open (US$) | E2: Low Open (US$) | F2: Close Open (US$) | G2: Volume | H2: Symbol | I2: Month | J2: Notes
B3: 44256 | C3: 4640805 | E3: 4570001 | F3: 4902376 | G3: 307922 | H3: BTCUSD | I3: Mar | J3: 6. High has 1 missing data point, which are unlikely to affect any calculation based on 615 of data points.
B4: 44317 | C4: 5827225 | D4: 30000000 | E4: 5640862 | F4: 5654740 | G4: 53894 | H4: BTCUSD | I4: May | J4: 7. There is one high data point that is 4 times larger than the second largest data point

Sheet Upside
B2: Symbol | C2: First open date | D2: Last close date | E2: First open (US$) | F2: Last close (US$) | G2: First open | H2: Last close | I2: Change
B3: BTCUSD | C3: =MIN(Data!B:B) -> 44200 | D3: =MAX(Data!B:B) -> 44561 | E3: {=INDEX(Data!E:E, MATCH(1, (Table2[[#This Row],[First open date]]=Data!B:B)*(Table2[[#This Row],[Symbol]]=Data!K:K), 0))} -> 3361730 | F3: {=INDEX(Data!H:H, MATCH(1, (Table2[[#This Row],[Last close date]]=Data!B:B)*(Table2[[#This Row],[Symbol]]=Data!K:K), 0))} -> 4680683 | G3: =100% -> 1 | H3: =Table2[[#This Row],[Last close (US$)]]/Table2[[#This Row],[First open (US$)]] -> 1.3923435 | I3: =Table2[[#This Row],[Last close]]-Table2[[#This Row],[First open]] -> 0.39234353
B4: SP500 | C4: =MIN(Data!B:B) -> 44200 | D4: =MAX(Data!B:B) -> 44561 | E4: {=INDEX(Data!E:E, MATCH(1, (Table2[[#This Row],[First open date]]=Data!B:B)*(Table2[[#This Row],[Symbol]]=Data!K:K), 0))} -> 376461 | F4: {=INDEX(Data!H:H, MATCH(1, (Table2[[#This Row],[Last close date]]=Data!B:B)*(Table2[[#This Row],[Symbol]]=Data!K:K), 0))} -> 476618 | G4: =100% -> 1 | H4: =Table2[[#This Row],[Last close (US$)]]/Table2[[#This Row],[First open (US$)]] -> 1.2660488 | I4: =Table2[[#This Row],[Last close]]-Table2[[#This Row],[First open]] -> 0.26604881

Sheet Spread
B2: Symbol | C2: Smallest low (US$) | D2: Largest high (US$) | E2: Smallest low | F2: Largest high
B3: BTCUSD | C3: {=MIN(IF(Data!K:K=Table3[[#This Row],[Symbol]],Data!G:G))} -> 2763234 | D3: {=MAX(IF(Data!K:K=Table3[[#This Row],[Symbol]],Data!F:F))} -> 6900000 | E3: =Table3[[#This Row],[Smallest low (US$)]]/Table3[[#This Row],[Largest high (US$)]] -> 0.4004687 | F3: =100% -> 1
B4: SP500 | C4: {=MIN(IF(Data!K:K=Table3[[#This Row],[Symbol]],Data!G:G))} -> 366271 | D4: {=MAX(IF(Data!K:K=Table3[[#This Row],[Symbol]],Data!F:F))} -> 480893 | E4: =Table3[[#This Row],[Smallest low (US$)]]/Table3[[#This Row],[Largest high (US$)]] -> 0.7616476 | F4: =100% -> 1

Sheet Exploratory Data Analysis
B2: Average of Close | C2: Column Labels
B3: Row Labels | C3: BTCUSD | D3: SP500 | E3: (blank) | F3: Grand Total
B4: Jan | C4: 3483491.7 | D4: 379374.84 | F4: 2228636
B5: Feb | C5: 4641937 | D5: 388343.21 | F5: 2922399.1
B6: Mar | C6: 5494663.5 | D6: 391050.83 | F6: 3279888.2
B7: Apr | C7: 5705380.5 | D7: 414117.62 | F7: 3526625.2
B8: May | C8: 4605342.7 | D8: 416784.95 | F8: 2929919.6
B9: Jun | C9: 3571823.7 | D9: 423848.95 | F9: 2239988.2
B10: Jul | C10: 3442799.6 | D10: 436371.29 | F10: 2228665.1
B11: Aug | C11: 4561923.5 | D11: 445396.59 | F11: 2853176.5
B12: Sep | C12: 4603419.5 | D12: 444554.33 | F12: 2890945.6
B13: Oct | C13: 5808966.5 | D13: 446070.71 | F13: 3643181.6
B14: Nov | C14: 6056054.1 | D14: 466738.67 | F14: 3754571.3
B15: Dec | C15: 4929997.5 | D15: 467477.27 | F15: 3077630.6
B16: (blank)
B17: Grand Total | C17: 4749074.5 | D17: 427338.56 | F17: 2969536.2
B19: Sum of High | C19: Column Labels
B20: Row Labels | C20: BTCUSD | D20: SP500 | E20: Grand Total
B21: 04/Jan | C21: 3366900 | D21: 376999 | E21: 3743899
B22: 05/Jan | C22: 3453629 | D22: 373783 | E22: 3827412
B23: 06/Jan | C23: 3782448 | D23: 378304 | E23: 4160752
B24: 07/Jan | C24: 4039600 | D24: 381155 | E24: 4420755
B25: 08/Jan | C25: 4199999 | D25: 382669 | E25: 4582668
B26: 09/Jan | C26: 4147021 | E26: 4147021
B27: 10/Jan | C27: 4119662 | E27: 4119662
B28: 11/Jan | C28: 3632325 | D28: 381786 | E28: 4014111
B29: 12/Jan | C29: 3665134 | D29: 381078 | E29: 4046212
B30: 13/Jan | C30: 3818833 | D30: 382096 | E30: 4200929
B31: 14/Jan | C31: 4011279 | D31: 382360 | E31: 4393639
B32: 15/Jan | C32: 3884996 | D32: 378873 | E32: 4263869
B33: 16/Jan | C33: 3794971 | E33: 3794971
B34: 17/Jan | C34: 3684011 | E34: 3684011
B35: 18/Jan | C35: 3746921 | E35: 3746921
B36: 19/Jan | C36: 3793420 | D36: 380453 | E36: 4173873
B37: 20/Jan | C37: 3596495 | D37: 385975 | E37: 3982470
B38: 21/Jan | C38: 3500000 | D38: 386145 | E38: 3886145
B39: 22/Jan | C39: 3388000 | D39: 385231 | E39: 3773231
B40: 23/Jan | C40: 3347949 | E40: 3347949
B41: 24/Jan | C41: 3367218 | E41: 3367218
B42: 25/Jan | C42: 3488556 | D42: 385923 | E42: 3874479
...

Sheet Final Recommendation
B2: Bitcoin might be a more interesting investment as compared to the SP500, if you can tolerate the increased volatility.
